[2025-09-22T08:23:13.555+0000] {local_task_job_runner.py:120} INFO - ::group::Pre task execution logs
[2025-09-22T08:23:13.990+0000] {taskinstance.py:2076} INFO - Dependencies all met for dep_context=non-requeueable deps ti=<TaskInstance: dbt_intermediate.intermediate.marital_statuses.run scheduled__2025-09-21T00:00:00+00:00 [queued]>
[2025-09-22T08:23:14.009+0000] {taskinstance.py:2076} INFO - Dependencies all met for dep_context=requeueable deps ti=<TaskInstance: dbt_intermediate.intermediate.marital_statuses.run scheduled__2025-09-21T00:00:00+00:00 [queued]>
[2025-09-22T08:23:14.018+0000] {taskinstance.py:2306} INFO - Starting attempt 1 of 1
[2025-09-22T08:23:14.061+0000] {taskinstance.py:2330} INFO - Executing <Task(DbtRunVirtualenvOperator): intermediate.marital_statuses.run> on 2025-09-21 00:00:00+00:00
[2025-09-22T08:23:14.071+0000] {standard_task_runner.py:64} INFO - Started process 3939 to run task
[2025-09-22T08:23:14.075+0000] {standard_task_runner.py:90} INFO - Running: ['***', 'tasks', 'run', 'dbt_intermediate', 'intermediate.marital_statuses.run', 'scheduled__2025-09-21T00:00:00+00:00', '--job-id', '682', '--raw', '--subdir', 'DAGS_FOLDER/dbt_intermediate.py', '--cfg-path', '/tmp/tmp7p6k684w']
[2025-09-22T08:23:14.080+0000] {standard_task_runner.py:91} INFO - Job 682: Subtask intermediate.marital_statuses.run
[2025-09-22T08:23:14.540+0000] {task_command.py:426} INFO - Running <TaskInstance: dbt_intermediate.intermediate.marital_statuses.run scheduled__2025-09-21T00:00:00+00:00 [running]> on host e95bde6b8d07
[2025-09-22T08:23:15.151+0000] {taskinstance.py:2648} INFO - Exporting env vars: AIRFLOW_CTX_DAG_OWNER='***' AIRFLOW_CTX_DAG_ID='dbt_intermediate' AIRFLOW_CTX_TASK_ID='intermediate.marital_statuses.run' AIRFLOW_CTX_EXECUTION_DATE='2025-09-21T00:00:00+00:00' AIRFLOW_CTX_TRY_NUMBER='1' AIRFLOW_CTX_DAG_RUN_ID='scheduled__2025-09-21T00:00:00+00:00'
[2025-09-22T08:23:15.157+0000] {taskinstance.py:430} INFO - ::endgroup::
[2025-09-22T08:23:15.182+0000] {virtualenv.py:120} INFO - Checking if the virtualenv lock /opt/***/cosmos_venvs/ecom_intermediate/cosmos_virtualenv.lock exists
[2025-09-22T08:23:15.187+0000] {virtualenv.py:126} INFO - Acquiring the virtualenv lock
[2025-09-22T08:23:15.192+0000] {virtualenv.py:195} INFO - Acquiring lock at /opt/***/cosmos_venvs/ecom_intermediate/cosmos_virtualenv.lock with pid 3939
[2025-09-22T08:23:15.194+0000] {virtualenv.py:153} INFO - Creating or updating the virtualenv at `/opt/***/cosmos_venvs/ecom_intermediate
[2025-09-22T08:23:15.195+0000] {process_utils.py:183} INFO - Executing cmd: /home/***/.local/bin/python -m virtualenv /opt/***/cosmos_venvs/ecom_intermediate --python=python3
[2025-09-22T08:23:15.199+0000] {process_utils.py:187} INFO - Output:
[2025-09-22T08:23:17.020+0000] {process_utils.py:191} INFO - RuntimeError: failed to build image pip because:
[2025-09-22T08:23:17.022+0000] {process_utils.py:191} INFO - Traceback (most recent call last):
[2025-09-22T08:23:17.022+0000] {process_utils.py:191} INFO -   File "/home/***/.local/lib/python3.10/site-packages/virtualenv/seed/embed/via_app_data/via_app_data.py", line 57, in _install
[2025-09-22T08:23:17.023+0000] {process_utils.py:191} INFO -     installer.install(creator.interpreter.version_info)
[2025-09-22T08:23:17.024+0000] {process_utils.py:191} INFO -   File "/home/***/.local/lib/python3.10/site-packages/virtualenv/seed/embed/via_app_data/pip_install/base.py", line 37, in install
[2025-09-22T08:23:17.024+0000] {process_utils.py:191} INFO -     self._sync(filename, into)
[2025-09-22T08:23:17.025+0000] {process_utils.py:191} INFO -   File "/home/***/.local/lib/python3.10/site-packages/virtualenv/seed/embed/via_app_data/pip_install/copy.py", line 13, in _sync
[2025-09-22T08:23:17.025+0000] {process_utils.py:191} INFO -     copy(src, dst)
[2025-09-22T08:23:17.030+0000] {process_utils.py:191} INFO -   File "/home/***/.local/lib/python3.10/site-packages/virtualenv/util/path/_sync.py", line 41, in copy
[2025-09-22T08:23:17.031+0000] {process_utils.py:191} INFO -     method(str(src), str(dest))
[2025-09-22T08:23:17.032+0000] {process_utils.py:191} INFO -   File "/home/***/.local/lib/python3.10/site-packages/virtualenv/util/path/_sync.py", line 52, in copytree
[2025-09-22T08:23:17.033+0000] {process_utils.py:191} INFO -     shutil.copy(src_f, dest_f)
[2025-09-22T08:23:17.034+0000] {process_utils.py:191} INFO -   File "/usr/local/lib/python3.10/shutil.py", line 417, in copy
[2025-09-22T08:23:17.035+0000] {process_utils.py:191} INFO -     copyfile(src, dst, follow_symlinks=follow_symlinks)
[2025-09-22T08:23:17.036+0000] {process_utils.py:191} INFO -   File "/usr/local/lib/python3.10/shutil.py", line 256, in copyfile
[2025-09-22T08:23:17.036+0000] {process_utils.py:191} INFO -     with open(dst, 'wb') as fdst:
[2025-09-22T08:23:17.037+0000] {process_utils.py:191} INFO - FileNotFoundError: [Errno 2] No such file or directory: '/opt/***/cosmos_venvs/ecom_intermediate/lib/python3.10/site-packages/pip/_internal/vcs/versioncontrol.py'
[2025-09-22T08:23:17.038+0000] {process_utils.py:191} INFO - 
[2025-09-22T08:23:17.107+0000] {virtualenv.py:131} INFO - Releasing virtualenv lock
[2025-09-22T08:23:17.109+0000] {virtualenv.py:210} WARNING - Lockfile owned by process of pid 3942, while operator has pid 3939
[2025-09-22T08:23:17.110+0000] {taskinstance.py:441} INFO - ::group::Post task execution logs
[2025-09-22T08:23:17.111+0000] {taskinstance.py:2905} ERROR - Task failed with exception
Traceback (most recent call last):
  File "/home/airflow/.local/lib/python3.10/site-packages/airflow/models/taskinstance.py", line 465, in _execute_task
    result = _execute_callable(context=context, **execute_callable_kwargs)
  File "/home/airflow/.local/lib/python3.10/site-packages/airflow/models/taskinstance.py", line 432, in _execute_callable
    return execute_callable(context=context, **execute_callable_kwargs)
  File "/home/airflow/.local/lib/python3.10/site-packages/airflow/models/baseoperator.py", line 401, in wrapper
    return func(self, *args, **kwargs)
  File "/home/airflow/.local/lib/python3.10/site-packages/cosmos/operators/virtualenv.py", line 144, in execute
    output = super().execute(context)
  File "/home/airflow/.local/lib/python3.10/site-packages/cosmos/operators/base.py", line 310, in execute
    self.build_and_run_cmd(context=context, cmd_flags=self.add_cmd_flags())
  File "/home/airflow/.local/lib/python3.10/site-packages/cosmos/operators/local.py", line 853, in build_and_run_cmd
    result = self.run_command(
  File "/home/airflow/.local/lib/python3.10/site-packages/cosmos/operators/virtualenv.py", line 128, in run_command
    self._py_bin = self._prepare_virtualenv()
  File "/home/airflow/.local/lib/python3.10/site-packages/cosmos/operators/virtualenv.py", line 154, in _prepare_virtualenv
    py_bin = prepare_virtualenv(
  File "/home/airflow/.local/lib/python3.10/site-packages/airflow/utils/python_virtualenv.py", line 105, in prepare_virtualenv
    execute_in_subprocess(virtualenv_cmd)
  File "/home/airflow/.local/lib/python3.10/site-packages/airflow/utils/process_utils.py", line 172, in execute_in_subprocess
    execute_in_subprocess_with_kwargs(cmd, cwd=cwd)
  File "/home/airflow/.local/lib/python3.10/site-packages/airflow/utils/process_utils.py", line 195, in execute_in_subprocess_with_kwargs
    raise subprocess.CalledProcessError(exit_code, cmd)
subprocess.CalledProcessError: Command '['/home/airflow/.local/bin/python', '-m', 'virtualenv', '/opt/airflow/cosmos_venvs/ecom_intermediate', '--python=python3']' returned non-zero exit status 1.
[2025-09-22T08:23:17.176+0000] {taskinstance.py:1206} INFO - Marking task as FAILED. dag_id=dbt_intermediate, task_id=intermediate.marital_statuses.run, run_id=scheduled__2025-09-21T00:00:00+00:00, execution_date=20250921T000000, start_date=20250922T082313, end_date=20250922T082317
[2025-09-22T08:23:17.215+0000] {standard_task_runner.py:110} ERROR - Failed to execute job 682 for task intermediate.marital_statuses.run (Command '['/home/airflow/.local/bin/python', '-m', 'virtualenv', '/opt/airflow/cosmos_venvs/ecom_intermediate', '--python=python3']' returned non-zero exit status 1.; 3939)
[2025-09-22T08:23:17.236+0000] {local_task_job_runner.py:243} INFO - Task exited with return code 1
[2025-09-22T08:23:17.312+0000] {taskinstance.py:3503} INFO - 0 downstream tasks scheduled from follow-on schedule check
[2025-09-22T08:23:17.327+0000] {local_task_job_runner.py:222} INFO - ::endgroup::
